## 15.1 处理错误

- 使用异常警示错误的主要优势是，错误处理代码和导致错误的代码被完全隔离开。



## 15.2 理解异常

- 异常是任意类型的临时对象，用于警示错误。理论上，异常可以是基本类型的对象，但通常是专门为了处理错误而定义的类对象。异常对象可以把错误信息传送给错误处理的代码。
- 当发错发生时，会通过“抛出”异常来警示错误，异常对象会传送到捕获并处理它的代码块。
- 使用try{}来包含可能抛出异常的代码，try{}称为try块。如果不在try块的语句抛出异常，或try块抛出的异常未被捕获，则程序就会终止。
- try块后面是一到多个catch块。每个catch块包含处理某种异常的代码，因此catch块被称为异常处理程序。只有当与抛出的异常类型匹配时，catch块的代码才会执行。

### 案例1：抛出异常

```c++
static void test1() {
	cout << "---------测试：抛出异常---------" << endl;
	for (int i = 0; i < 6; i++) {
		try {
			if (i % 2 == 0) {
				throw "偶数";
			}
			cout << "未抛出偶数异常" << endl;
			if (i % 3 == 2) {
				throw 1;
			}
		}
		catch (const char* msg) {
			cout << "捕获异常：" << msg << endl;
		}
		catch (int i) {
			cout << "捕获异常：" << i << endl;
		}

		cout << "循环迭代一次" << endl;
	}	
}
// ret
---------测试：抛出异常---------
捕获异常：偶数
循环迭代一次
未抛出偶数异常
循环迭代一次
捕获异常：偶数
循环迭代一次
未抛出偶数异常
循环迭代一次
捕获异常：偶数
循环迭代一次
未抛出偶数异常
捕获异常：1
循环迭代一次
```

- 使用throw表达式来抛出异常。编译器在匹配异常类型和catch参数类型时，会忽略const关键字。
- try块的处理程序catch块必须紧跟在try块之后，则各个catch块之间不能有其他代码，否则编译出错。
- 当try中抛出异常后，try块中其后的代码就不会继续执行，而是转到catch处理程序中。
- 发生异常后不会结束程序，可以在处理程序中修复导致异常的问题。



### 案例2：异常处理过程

```c++
class Box15_2_2_1 {
public:
	~Box15_2_2_1() { cout << "Box1 析构函数\n"; }
};
// 私有的副本构造函数
class Box15_2_2_2 {
private:
	Box15_2_2_2(const Box15_2_2_2& box) { cout << "副本构造函数\n"; }
public:
	Box15_2_2_2() = default;
	~Box15_2_2_2() { cout << "Box2 析构函数\n"; }
	void show() { cout << "ha" << endl; }
};
// test
static void test2() {
	cout << "\n---------测试：异常处理过程---------" << endl;
	for (int i = 0; i < 6; i++) {
		cout << "迭代: " << i << endl;
		try {
			Box15_2_2_1 box;
			if (i % 2 == 1) {
				// 不能抛出使用私有副本构造函数的类的对象
				/*Box15_2_2_2 box1{};
				throw box1;*/
				throw Box15_2_2_2{};
			}
		}
		catch (const char* msg) {
			cout << "捕获异常：" << msg << endl;
			return;
		}
		catch (Box15_2_2_2& box ) {
			box.show();
		}
		cout << "try-catch结束" << endl;
	}
	
}
//  ret
迭代: 0
Box1 析构函数
try-catch结束
迭代: 1
Box1 析构函数
ha
Box2 析构函数
try-catch结束
迭代: 2
Box1 析构函数
try-catch结束
迭代: 3
Box1 析构函数
ha
Box2 析构函数
try-catch结束
迭代: 4
Box1 析构函数
try-catch结束
迭代: 5
Box1 析构函数
ha
Box2 析构函数
try-catch结束
```

- 异常处理过程：1、使用throw抛出一个对象。2、在try块中定义的所有自动对象调用析构函数。3、选择与返回异常对象类型相同的处理程序。4、使用异常对象的副本构造函数把catch参数初始化，此时控制权移交给处理程序。5、如果处理程序未结束程序，则继续执行try-catch之后的代码。
- try是一个语句块，当抛出异常后会退出try块，其中的对象会自动释放。所以不应该使用指向try中对象的指针作为返回的异常对象。
- 异常对象的类型必须是可以复制的。如果对象的副本构造函数是私有的、受保护的或者已经被删除，该对象不可以用于异常。但如果throw Box{}；而catch(Box& box)；Box仍可以作为异常对象。
- throw表达式用于初始化临时对象，因此创建了异常的一个副本。我们可以抛出try中的局部对象，然后通过副本构造函数来初始化catch的参数。
- catch块中使用return语句将控制权传送到catch块的外部。



### 案例3：导致抛出异常的代码

```c++
inline void fun15_2_2_1() {
	cout << "fun1" << endl;
}

inline void fun15_2_2_2() {
	cout << "fun2" << endl;
	throw "123";
}

inline void fun15_2_2_3() {
	fun15_2_2_2();
	cout << "fun3" << endl;
}
// test
static void test3() {
	cout << "\n---------测试：导致抛出异常的代码---------" << endl;
	try {
		fun15_2_2_1();
		fun15_2_2_3();
	}
	catch (const char* msg) {
		cout << "捕获异常：" << msg << endl;
	}
}
// ret
---------测试：导致抛出异常的代码---------
fun1
fun2
捕获异常：123
```

- 抛出异常的代码只需在逻辑上位于try块中即可。如果异常到达没有更多catch处理程序的一级，且仍未捕获，通常会结束程序。
- 应在程序结构和操作最方便的地方处理异常，极端情况在main中捕获所有异常。



### 案例4：嵌套的try块

- 人话：异常被抛出后，由最近的一个try来处理该异常，如果该try没处理，则继续找第二个最近的try块。



## 15.3 用类对象作为异常

- 异常对象的核心是与处理程序交流错误信息。因此通常设计一个特殊的类来表示某种类型的问题。
- 异常处理的思想通常是提供有关错误原因的信息，以帮助诊断问题。为了使异常处理的逻辑易于管理，需要确保异常类的成员函数不会抛出异常。
- catch块的参数可以使用引用，以避免不必要的引用。



### 案例1：匹配catch处理程序和异常

```c++
class Oops15_3_1_1 {
protected:
	string msg;
public:
	Oops15_3_1_1(const string& m="普通错误") : msg{m} {}

	virtual string getMsg() const { return msg; }
};

class MoreOops : public Oops15_3_1_1 {
public:
	MoreOops(const string& m = "中级错误") :Oops15_3_1_1{m}{}
};

class BigOops : public MoreOops {
public:
	BigOops(const string& m = "重大") :MoreOops{ m } {}
};
//  test
static void test1() {
	cout << "\n------测试1：匹配catch处理程序和异常\n";

	for (int i = 0; i < 3; i++) {
		try {
			if (i == 0) { throw Oops15_3_1_1{}; }
			if (i == 1) { throw MoreOops{}; }
			if (i == 2) { throw BigOops{}; }
		}
		catch (BigOops& oops) {
			cout << "1" << oops.getMsg() << endl;
		}
		catch (MoreOops& oops) {
			cout << "2" << oops.getMsg() << endl;
		}
		catch (Oops15_3_1_1& oops) {
			cout << "3" << oops.getMsg() << endl;
		}
	}
}
//  ret
------测试1：匹配catch处理程序和异常
3普通错误
2中级错误
1重大
```

- 跟在try块后面的处理程序会按照代码的顺序进行检查，并执行第一个参数类型与异常对象类型匹配的处理程序。对于基本类型，需要与异常对象的类型完全匹配。对于类类型，可能进行隐式转换或者多态来匹配。
- 匹配成功的规则按照下面的顺序：
  - 参数类型与异常类型完全匹配，忽略const。
  - 参数类型是异常的直接或间接基类，或其相关引用，忽略const。
  - 参数和异常都是指针，异常类型可以隐式转参数类型，忽略const。
- 基于上述原则，如果参数类型中存在继承关系，应将特殊的类放在最上面，一般的类放在下面。



### 案例2：用基类处理程序捕获派生类异常

```c++
class Oops15_3_1_1 {
protected:
	string msg;
public:
	Oops15_3_1_1(const string& m="普通错误") : msg{m} {}
	virtual string getMsg() const { return msg; }
};
class MoreOops : public Oops15_3_1_1 {
public:
	MoreOops(const string& m = "中级错误") :Oops15_3_1_1{m}{}
};
class BigOops : public MoreOops {
public:
	BigOops(const string& m = "重大") :MoreOops{ m } {}
};
// test
static void test2() {
	cout << "\n------测试2：用基类处理程序捕获派生类异常\n";
	cout << "catch按引用接收" << endl;
	for (int i = 0; i < 3; i++) {
		try {
			if (i == 0) { throw Oops15_3_1_1{}; }
			if (i == 1) { throw MoreOops15_3_1_1{}; }
			if (i == 2) { throw BigOops15_3_1_1{}; }
		}
		catch (Oops15_3_1_1& oops) {
			cout << typeid(oops).name() << endl;
			cout << oops.getMsg() << endl;
		}
	}
	cout << "catch按值接收" << endl;
	for (int i = 0; i < 3; i++) {
		try {
			if (i == 0) { throw Oops15_3_1_1{}; }
			if (i == 1) { throw MoreOops15_3_1_1{}; }
			if (i == 2) { throw BigOops15_3_1_1{}; }
		}
		catch (Oops15_3_1_1 oops) {
			cout << typeid(oops).name() << endl;
			cout << oops.getMsg() << endl;
		}
	}
}
// ret
catch按引用接收
class Oops15_3_1_1
普通错误
class MoreOops15_3_1_1
中级错误
class BigOops15_3_1_1
重大
catch按值接收
class Oops15_3_1_1
普通错误
class Oops15_3_1_1
中级错误
class Oops15_3_1_1
重大
```

- 按引用捕获异常对象时，其动态类型保持不变。
- 按值捕获异常对象时，无法保持动态类型，会发生对象切片，派生类特有的属性将失去。
- 黄金法则：总是按值抛出异常，按引用捕获异常。按值抛出：指不能抛出使用new创建的异常，也不应该按值捕获异常，导致多余的副本或对象切片。



## 15.4 重新抛出异常

```c++
class Oops15_4_1 {
protected:
	string msg;
public:
	Oops15_4_1(const string& m = "普通错误") : msg{ m } {}
	virtual ~Oops15_4_1() { cout << "Oops 析构函数" << endl; }
	virtual string getMsg() const { return msg; }
};

class MoreOops15_4_1 : public Oops15_4_1 {
public:
	MoreOops15_4_1(const string& m = "中级错误") { msg = m; }
	~MoreOops15_4_1() {	cout << "MoreOops 析构函数" << endl; }
};
// test
static void test1() {
	cout << "\n------测试1：重新抛出异常\n";
	Oops15_4_1 oops;
	MoreOops15_4_1 mOops;

	for (int i = 0; i < 2; i++) {
		cout << "迭代次数: " << i << endl;
		try {
			try {
 				if (i == 0) { throw oops; }
				else { throw mOops; }
			}
			catch (Oops15_4_1& oops) {
				if (typeid(oops) == typeid(MoreOops15_4_1)) { throw; }
				cout << "捕获异常：Oops15_4_1" << endl;
			}
		}
		catch (Oops15_4_1& moreOops) { cout << "捕获异常：MoreOops15_4_1" << endl; }

	}
	cout << "\nfor 循环结束\n";

}

static void test2() {
	cout << "\n------测试2：重新抛出异常,throw 对象\n";
	Oops15_4_1 oops;
	MoreOops15_4_1 mOops;
    
	for (int i = 0; i < 2; i++) {
		cout << "迭代次数: " << i << endl;
		try {
			try {
				if (i == 0) { throw oops; }
				else { throw mOops; }
			}
			catch (Oops15_4_1& oops) {
				if (typeid(oops) == typeid(MoreOops15_4_1)) { throw oops; }
				cout << "捕获异常：Oops15_4_1" << endl;
			}
		}
		catch (Oops15_4_1& moreOops) { cout << "捕获异常：MoreOops15_4_1" << endl; }
	}
	cout << "\nfor 循环结束\n";
}
// ret
------测试1：重新抛出异常
迭代次数: 0
捕获异常：Oops15_4_1
Oops 析构函数
迭代次数: 1
捕获异常：MoreOops15_4_1
MoreOops 析构函数
Oops 析构函数

for 循环结束
MoreOops 析构函数
Oops 析构函数
Oops 析构函数

------测试2：重新抛出异常,throw 对象
迭代次数: 0
捕获异常：Oops15_4_1
Oops 析构函数
迭代次数: 1
MoreOops 析构函数
Oops 析构函数
捕获异常：MoreOops15_4_1
Oops 析构函数

for 循环结束
MoreOops 析构函数
Oops 析构函数
Oops 析构函数
```

- 在处理程序中捕获一个异常时，可以重新抛出该异常，让外层的try块捕获它。使用 throw; 语句即可。此时将捕获的对象直接抛出，而不是复制它。
- 显示指定异常对象的语句( throw oops; )会抛出新的异常，而不是原来的异常。此时如果捕获的异常是catch参数类型的派生类，抛出的对象则会发生对象切片。



## 15.5 未处理的异常

- 如果抛出的异常没有被直接或间接捕获，那么程序就会立即结束，即立即崩溃。
- 程序中未被捕获的异常会调用 std::terminate();该函数会调用默认终止处理函数，默认终止处理函数会调用std::abort();。技术上可以通过set_terminate()传送一个函数指针，重写std::terminate()的行为，但并不推荐。
- 异常被未捕获，说明程序发生了错误，如果不结束程序，可能发生更大的错误，所以处理的合理方案就是中断执行。



## 15.6 捕获所有的异常

- 将catch块的参数使用 ... 来作参数，说明该catch块处理所有类型的异常。通常该块位于最后。
- 实际开发中尽量不使用... 来捕获异常，进行相应的错误处理。



## 15.7 不抛出异常的函数

- 技术上任何函数都可以抛出异常，但实际情况有些函数不应该抛出异常。

### 案例1：noexcept 限定符

```c++
class Class15_7_1_1 {
public:
	static void  fun() noexcept {
		try { throw 1; }
		catch (int& i) { cout << "i: " << i << endl; }
	}
	static void  fun_except() noexcept {
		try {
            //throw 3.1;// 程序在此处崩溃 
        }
		catch (int& i) {
			cout << "i: " << i << endl;
		}
	}
};
```

- 在函数体前使用noexcept限定符修饰，可指定该函数不可抛出异常。
- noexcept表示该函数不会抛出异常，即函数内可以捕获异常，但函数内发生的所有异常不可再向外抛出(即异常不能离开当前函数)，一旦抛出给调用该函数的函数，程序就会终止。
- 可以对所有函数使用noexcept。
- C++17标准之前，在函数体前可以使用throw(Type1,Type2..)来指定可以抛出的异常类型列表。但C++17不再支持，只保留了throw()，且使用noexcept限定符来替换该用法。



### 案例2：异常和析构函数

```c++
class Class15_7_2_1 {
public:
	// 抛出异常会终止程序
	~Class15_7_2_1()  { throw 1; }
};
class Class15_7_2_2 {
public:
	// 显式声明可以抛出异常
	~Class15_7_2_2() noexcept(false) { throw 1; }
};
// test
static void test2() {
	cout << "----------测试2: 异常和析构函数" << endl;
	//Class15_7_2_1 a;// 会test2代码执行完后终止程序

	try {
		Class15_7_2_2 b;
	}
	catch (int a) {
		cout << a << endl;
	}
}
// ret
----------测试2: 异常和析构函数
1
```

- C++11开始，编译器会将析构函数隐式添加上noexcept限定符。
- 原则上可以显示添加noexcept(false)来是析构函数可以抛出异常，但不推荐。



## 15.8 异常和资源泄露

- 确保捕获所有异常，可以避免程序终止。但由于try块中发生抛出异常后，抛出异常后续的代码就不会执行，所以可能隐藏bug。
- 典型的例子：抛出异常前使用new分配了内存，但是delete内存是发生在throw代码之后的，如果发生了异常，则delete释放内存的函数将不会执行，即发生内存泄漏。



### 案例1：资源获取即初始化

```c++
inline int* fun15_8_1() {

	int* res{ nullptr };
	try {
		// 申请资源
		int* arr = new int[100];
		arr[1] = 10;
		res = arr;
		// 可能抛出异常的计算
		throw 1;
		// 释放资源
		delete[] arr;
	}
	catch (int a) { cout << a << endl; }
	cout <<"数组访问：" << res[1] << endl;
}

class RAII15_8_1 {
private:
	int* res;
public:
	RAII15_8_1(int size) {
		res = new int[size];
		res[1] = 10;
	}
	~RAII15_8_1() {
		cout << "RAII 析构函数\n";
		delete[] res;
	}
	int* release() {
		int* rel = res;
		res = nullptr;
		return rel;
	}
	int* get() { return res; }

};

inline void fun15_8_2() {
	int* res{ nullptr };
	try {
		// 申请资源
		RAII15_8_1 arr{ 100 };
		res = arr.get();
		// 可能抛出异常的计算
		throw 1;
		// 命名空间结束，自动释放资源
	}
	catch (int a) { cout << a << endl; }
	// 原先的数据失效，且只能访问该内存，不能进行写操作
	cout << "数组访问：" << res[1] << endl;
	//delete res;
}
// test
static void test1() {
	cout << "----------测试1: 资源获取即初始化" << endl;
	fun15_8_1();
	fun15_8_2();
}
// ret
1
数组访问：10
RAII 析构函数
1
数组访问：505
```

- RAII:资源获取即初始化。其前提是每次获取资源时，应当通过初始化一个对象来获取。每个资源由一个对象进行管理，该对象要么在栈上，要么是一个成员变量。因此，避免资源泄露迭代技巧是，默认情况下，对象的析构函数来释放资源。
- 由于异常的抛出，throw后续的代码不会执行，所以可能导致释放内存的操作无法进行，因此而造成内存泄漏。但如果通过在try外面来保存需要释放的内存时，很能操作。所以可通过RAII对象的方式来管理内存，当抛出异常后，由于RAII对象在try中，会被调用析构函数，此时保证了内存的释放。
- 任何时候都建议使用RAII来管理资源。



### 案例2：用于动态内存的标准RAII类

```c++
inline unique_ptr<int[]> fun15_8_2_1() {
	auto arr = make_unique<int[]>(100);
	throw 1;
	return arr;
}
// test
static void test2() {
	cout << "----------测试2: 用于动态内存的标准RAII类" << endl;
	try {
		// 要是出现异常,arr不会被赋值
		auto arr = fun15_8_2_1();
	}
	catch (int i) { cout << i << endl; }
}
// ret
1
```

- 实际应用中不会编写RAII类来管理资源，而是使用标准库提供的一些工具。
- 在<memory>中的unique_ptr<>就是一个RAII类，通过传送RAII对象即可实现资源的自动管理。
- unique_ptr<>的副本构造函数也被删除，但该类启动了移动语义。
- 所有动态内存都应该由一个RAII对象管理，对于使用new运算符的操作，应该优先使用智能指针来替换。



## 15.9 标准库的异常







## 15.10 本章小结

















































